{"primaryContentSections":[{"kind":"declarations","declarations":[{"tokens":[{"kind":"keyword","text":"func"},{"kind":"text","text":" "},{"kind":"identifier","text":"whenFailureBlocking"},{"kind":"text","text":"("},{"kind":"externalParam","text":"onto"},{"kind":"text","text":" "},{"kind":"internalParam","text":"queue"},{"kind":"text","text":": "},{"kind":"typeIdentifier","text":"DispatchQueue","preciseIdentifier":"c:objc(cs)OS_dispatch_queue"},{"kind":"text","text":", "},{"kind":"externalParam","text":"_"},{"kind":"text","text":" "},{"kind":"internalParam","text":"callbackMayBlock"},{"kind":"text","text":": "},{"kind":"attribute","text":"@escaping"},{"kind":"text","text":" ("},{"kind":"typeIdentifier","text":"Error","preciseIdentifier":"s:s5ErrorP"},{"kind":"text","text":") -> "},{"kind":"typeIdentifier","text":"Void","preciseIdentifier":"s:s4Voida"},{"kind":"text","text":")"}],"languages":["swift"],"platforms":["macOS"]}]},{"kind":"parameters","parameters":[{"name":"onto","content":[{"type":"paragraph","inlineContent":[{"type":"text","text":"the "},{"type":"codeVoice","code":"DispatchQueue"},{"type":"text","text":" on which the blocking IO \/ task specified by "},{"type":"codeVoice","code":"callbackMayBlock"},{"type":"text","text":" is scheduled."}]}]},{"name":"callbackMayBlock","content":[{"type":"paragraph","inlineContent":[{"type":"text","text":"The callback that is called with the failed result of the "},{"type":"codeVoice","code":"EventLoopFuture"},{"type":"text","text":"."}]}]}]},{"kind":"content","content":[{"anchor":"discussion","level":2,"type":"heading","text":"Discussion"},{"type":"paragraph","inlineContent":[{"type":"text","text":"An observer callback cannot return a value, meaning that this function cannot be chained"},{"type":"text","text":" "},{"type":"text","text":"from. If you are attempting to create a computation pipeline, consider "},{"type":"codeVoice","code":"recover"},{"type":"text","text":" or "},{"type":"codeVoice","code":"flatMapError"},{"type":"text","text":"."},{"type":"text","text":" "},{"type":"text","text":"If you find yourself passing the results from this "},{"type":"codeVoice","code":"EventLoopFuture"},{"type":"text","text":" to a new "},{"type":"codeVoice","code":"EventLoopPromise"},{"type":"text","text":" "},{"type":"text","text":"in the body of this function, consider using "},{"type":"codeVoice","code":"cascade"},{"type":"text","text":" instead."}]}]}],"schemaVersion":{"major":0,"minor":3,"patch":0},"sections":[],"variants":[{"paths":["\/documentation\/nio\/eventloopfuture\/whenfailureblocking(onto:_:)"],"traits":[{"interfaceLanguage":"swift"}]}],"identifier":{"url":"doc:\/\/org.swift.docc\/documentation\/NIO\/EventLoopFuture\/whenFailureBlocking(onto:_:)","interfaceLanguage":"swift"},"abstract":[{"type":"text","text":"Adds an observer callback to this "},{"type":"codeVoice","code":"EventLoopFuture"},{"type":"text","text":" that is called when the"},{"type":"text","text":" "},{"type":"codeVoice","code":"EventLoopFuture"},{"type":"text","text":" has a failure result. The observer callback is permitted to block."}],"kind":"symbol","metadata":{"role":"symbol","title":"whenFailureBlocking(onto:_:)","roleHeading":"Instance Method","fragments":[{"kind":"keyword","text":"func"},{"kind":"text","text":" "},{"kind":"identifier","text":"whenFailureBlocking"},{"kind":"text","text":"("},{"kind":"externalParam","text":"onto"},{"kind":"text","text":": "},{"kind":"typeIdentifier","text":"DispatchQueue","preciseIdentifier":"c:objc(cs)OS_dispatch_queue"},{"kind":"text","text":", ("},{"kind":"typeIdentifier","text":"Error","preciseIdentifier":"s:s5ErrorP"},{"kind":"text","text":") -> "},{"kind":"typeIdentifier","text":"Void","preciseIdentifier":"s:s4Voida"},{"kind":"text","text":")"}],"symbolKind":"method","externalID":"s:3NIO15EventLoopFutureC19whenFailureBlocking4onto_ySo17OS_dispatch_queueC_ys5Error_pctF","extendedModule":"NIO","modules":[{"name":"NIO"}]},"hierarchy":{"paths":[["doc:\/\/org.swift.docc\/documentation\/NIO","doc:\/\/org.swift.docc\/documentation\/NIO\/EventLoopFuture"]]},"references":{"doc://org.swift.docc/documentation/NIO/EventLoopFuture/whenFailureBlocking(onto:_:)":{"role":"symbol","title":"whenFailureBlocking(onto:_:)","fragments":[{"kind":"keyword","text":"func"},{"kind":"text","text":" "},{"kind":"identifier","text":"whenFailureBlocking"},{"kind":"text","text":"("},{"kind":"externalParam","text":"onto"},{"kind":"text","text":": "},{"kind":"typeIdentifier","text":"DispatchQueue","preciseIdentifier":"c:objc(cs)OS_dispatch_queue"},{"kind":"text","text":", ("},{"kind":"typeIdentifier","text":"Error","preciseIdentifier":"s:s5ErrorP"},{"kind":"text","text":") -> "},{"kind":"typeIdentifier","text":"Void","preciseIdentifier":"s:s4Voida"},{"kind":"text","text":")"}],"abstract":[{"type":"text","text":"Adds an observer callback to this "},{"type":"codeVoice","code":"EventLoopFuture"},{"type":"text","text":" that is called when the"},{"type":"text","text":" "},{"type":"codeVoice","code":"EventLoopFuture"},{"type":"text","text":" has a failure result. The observer callback is permitted to block."}],"identifier":"doc:\/\/org.swift.docc\/documentation\/NIO\/EventLoopFuture\/whenFailureBlocking(onto:_:)","kind":"symbol","type":"topic","url":"\/documentation\/nio\/eventloopfuture\/whenfailureblocking(onto:_:)"},"doc://org.swift.docc/documentation/NIO/EventLoopFuture":{"role":"symbol","title":"EventLoopFuture","fragments":[{"kind":"keyword","text":"class"},{"kind":"text","text":" "},{"kind":"identifier","text":"EventLoopFuture"}],"abstract":[{"type":"text","text":"Holder for a result that will be provided later."}],"identifier":"doc:\/\/org.swift.docc\/documentation\/NIO\/EventLoopFuture","kind":"symbol","type":"topic","navigatorTitle":[{"kind":"identifier","text":"EventLoopFuture"}],"url":"\/documentation\/nio\/eventloopfuture"},"doc://org.swift.docc/documentation/NIO":{"role":"collection","title":"NIO","abstract":[],"identifier":"doc:\/\/org.swift.docc\/documentation\/NIO","kind":"symbol","type":"topic","url":"\/documentation\/nio"}}}