{"primaryContentSections":[{"kind":"declarations","declarations":[{"tokens":[{"kind":"keyword","text":"case"},{"kind":"text","text":" "},{"kind":"identifier","text":"dataReceivedInErrorState"},{"kind":"text","text":"("},{"kind":"typeIdentifier","text":"Error","preciseIdentifier":"s:s5ErrorP"},{"kind":"text","text":", "},{"kind":"typeIdentifier","identifier":"doc:\/\/org.swift.docc\/documentation\/NIO\/ByteBuffer","preciseIdentifier":"s:3NIO10ByteBufferV","text":"ByteBuffer"},{"kind":"text","text":")"}],"languages":["swift"],"platforms":["macOS"]}]}],"schemaVersion":{"major":0,"minor":3,"patch":0},"sections":[],"variants":[{"paths":["\/documentation\/nio\/bytetomessagedecodererror\/datareceivedinerrorstate(_:_:)"],"traits":[{"interfaceLanguage":"swift"}]}],"identifier":{"url":"doc:\/\/org.swift.docc\/documentation\/NIO\/ByteToMessageDecoderError\/dataReceivedInErrorState(_:_:)","interfaceLanguage":"swift"},"abstract":[{"type":"text","text":"More data has been received by a "},{"type":"codeVoice","code":"ByteToMessageHandler"},{"type":"text","text":" despite the fact that an error has previously been"},{"type":"text","text":" "},{"type":"text","text":"emitted. The associated "},{"type":"codeVoice","code":"Error"},{"type":"text","text":" is the error previously emitted and the "},{"type":"codeVoice","code":"ByteBuffer"},{"type":"text","text":" is the extra data that has"},{"type":"text","text":" "},{"type":"text","text":"been received. The common cause for this error to be emitted is the user not having torn down the "},{"type":"codeVoice","code":"Channel"},{"type":"text","text":" "},{"type":"text","text":"after previously an "},{"type":"codeVoice","code":"Error"},{"type":"text","text":" has been sent through the pipeline using "},{"type":"codeVoice","code":"fireErrorCaught"},{"type":"text","text":"."}],"kind":"symbol","metadata":{"fragments":[{"kind":"keyword","text":"case"},{"kind":"text","text":" "},{"kind":"identifier","text":"dataReceivedInErrorState"},{"kind":"text","text":"("},{"kind":"typeIdentifier","text":"Error","preciseIdentifier":"s:s5ErrorP"},{"kind":"text","text":", "},{"kind":"typeIdentifier","text":"ByteBuffer","preciseIdentifier":"s:3NIO10ByteBufferV"},{"kind":"text","text":")"}],"title":"ByteToMessageDecoderError.dataReceivedInErrorState(_:_:)","roleHeading":"Case","role":"symbol","symbolKind":"case","externalID":"s:3NIO25ByteToMessageDecoderErrorO014dataReceivedInF5StateyACs0F0_p_AA0B6BufferVtcACmF","modules":[{"name":"NIO"}]},"hierarchy":{"paths":[["doc:\/\/org.swift.docc\/documentation\/NIO","doc:\/\/org.swift.docc\/documentation\/NIO\/ByteToMessageDecoderError"]]},"references":{"doc://org.swift.docc/documentation/NIO/ByteToMessageDecoderError/dataReceivedInErrorState(_:_:)":{"role":"symbol","title":"ByteToMessageDecoderError.dataReceivedInErrorState(_:_:)","fragments":[{"kind":"keyword","text":"case"},{"kind":"text","text":" "},{"kind":"identifier","text":"dataReceivedInErrorState"},{"kind":"text","text":"("},{"kind":"typeIdentifier","text":"Error","preciseIdentifier":"s:s5ErrorP"},{"kind":"text","text":", "},{"kind":"typeIdentifier","text":"ByteBuffer","preciseIdentifier":"s:3NIO10ByteBufferV"},{"kind":"text","text":")"}],"abstract":[{"type":"text","text":"More data has been received by a "},{"type":"codeVoice","code":"ByteToMessageHandler"},{"type":"text","text":" despite the fact that an error has previously been"},{"type":"text","text":" "},{"type":"text","text":"emitted. The associated "},{"type":"codeVoice","code":"Error"},{"type":"text","text":" is the error previously emitted and the "},{"type":"codeVoice","code":"ByteBuffer"},{"type":"text","text":" is the extra data that has"},{"type":"text","text":" "},{"type":"text","text":"been received. The common cause for this error to be emitted is the user not having torn down the "},{"type":"codeVoice","code":"Channel"},{"type":"text","text":" "},{"type":"text","text":"after previously an "},{"type":"codeVoice","code":"Error"},{"type":"text","text":" has been sent through the pipeline using "},{"type":"codeVoice","code":"fireErrorCaught"},{"type":"text","text":"."}],"identifier":"doc:\/\/org.swift.docc\/documentation\/NIO\/ByteToMessageDecoderError\/dataReceivedInErrorState(_:_:)","kind":"symbol","type":"topic","url":"\/documentation\/nio\/bytetomessagedecodererror\/datareceivedinerrorstate(_:_:)"},"doc://org.swift.docc/documentation/NIO/ByteToMessageDecoderError":{"role":"symbol","title":"ByteToMessageDecoderError","fragments":[{"kind":"keyword","text":"enum"},{"kind":"text","text":" "},{"kind":"identifier","text":"ByteToMessageDecoderError"}],"abstract":[{"type":"text","text":"Common errors thrown by "},{"type":"codeVoice","code":"ByteToMessageDecoder"},{"type":"text","text":"s."}],"identifier":"doc:\/\/org.swift.docc\/documentation\/NIO\/ByteToMessageDecoderError","kind":"symbol","type":"topic","navigatorTitle":[{"kind":"identifier","text":"ByteToMessageDecoderError"}],"url":"\/documentation\/nio\/bytetomessagedecodererror"},"doc://org.swift.docc/documentation/NIO":{"role":"collection","title":"NIO","abstract":[],"identifier":"doc:\/\/org.swift.docc\/documentation\/NIO","kind":"symbol","type":"topic","url":"\/documentation\/nio"},"doc://org.swift.docc/documentation/NIO/ByteBuffer":{"role":"symbol","title":"ByteBuffer","fragments":[{"kind":"keyword","text":"struct"},{"kind":"text","text":" "},{"kind":"identifier","text":"ByteBuffer"}],"abstract":[{"type":"codeVoice","code":"ByteBuffer"},{"type":"text","text":" stores contiguously allocated raw bytes. It is a random and sequential accessible sequence of zero or"},{"type":"text","text":" "},{"type":"text","text":"more bytes (octets)."}],"identifier":"doc:\/\/org.swift.docc\/documentation\/NIO\/ByteBuffer","kind":"symbol","type":"topic","navigatorTitle":[{"kind":"identifier","text":"ByteBuffer"}],"url":"\/documentation\/nio\/bytebuffer"}}}