{"primaryContentSections":[{"kind":"declarations","declarations":[{"tokens":[{"kind":"keyword","text":"func"},{"kind":"text","text":" "},{"kind":"identifier","text":"throwIfErrorCaught"},{"kind":"text","text":"() "},{"kind":"keyword","text":"throws"}],"languages":["swift"],"platforms":["macOS"]}]},{"kind":"content","content":[{"anchor":"discussion","level":2,"type":"heading","text":"Discussion"},{"type":"paragraph","inlineContent":[{"type":"text","text":"The "},{"type":"codeVoice","code":"EmbeddedChannel"},{"type":"text","text":" will store an error some error travels the "},{"type":"codeVoice","code":"ChannelPipeline"},{"type":"text","text":" all the way past its end."}]}]}],"schemaVersion":{"major":0,"minor":3,"patch":0},"sections":[],"variants":[{"paths":["\/documentation\/nio\/embeddedchannel\/throwiferrorcaught()"],"traits":[{"interfaceLanguage":"swift"}]}],"identifier":{"url":"doc:\/\/org.swift.docc\/documentation\/NIO\/EmbeddedChannel\/throwIfErrorCaught()","interfaceLanguage":"swift"},"abstract":[{"type":"text","text":"This method will throw the error that is stored in the "},{"type":"codeVoice","code":"EmbeddedChannel"},{"type":"text","text":" if any."}],"kind":"symbol","metadata":{"fragments":[{"kind":"keyword","text":"func"},{"kind":"text","text":" "},{"kind":"identifier","text":"throwIfErrorCaught"},{"kind":"text","text":"() "},{"kind":"keyword","text":"throws"}],"title":"throwIfErrorCaught()","roleHeading":"Instance Method","role":"symbol","symbolKind":"method","externalID":"s:3NIO15EmbeddedChannelC18throwIfErrorCaughtyyKF","modules":[{"name":"NIO"}]},"hierarchy":{"paths":[["doc:\/\/org.swift.docc\/documentation\/NIO","doc:\/\/org.swift.docc\/documentation\/NIO\/EmbeddedChannel"]]},"references":{"doc://org.swift.docc/documentation/NIO":{"role":"collection","title":"NIO","abstract":[],"identifier":"doc:\/\/org.swift.docc\/documentation\/NIO","kind":"symbol","type":"topic","url":"\/documentation\/nio"},"doc://org.swift.docc/documentation/NIO/EmbeddedChannel/throwIfErrorCaught()":{"role":"symbol","title":"throwIfErrorCaught()","fragments":[{"kind":"keyword","text":"func"},{"kind":"text","text":" "},{"kind":"identifier","text":"throwIfErrorCaught"},{"kind":"text","text":"() "},{"kind":"keyword","text":"throws"}],"abstract":[{"type":"text","text":"This method will throw the error that is stored in the "},{"type":"codeVoice","code":"EmbeddedChannel"},{"type":"text","text":" if any."}],"identifier":"doc:\/\/org.swift.docc\/documentation\/NIO\/EmbeddedChannel\/throwIfErrorCaught()","kind":"symbol","type":"topic","url":"\/documentation\/nio\/embeddedchannel\/throwiferrorcaught()"},"doc://org.swift.docc/documentation/NIO/EmbeddedChannel":{"role":"symbol","title":"EmbeddedChannel","fragments":[{"kind":"keyword","text":"class"},{"kind":"text","text":" "},{"kind":"identifier","text":"EmbeddedChannel"}],"abstract":[{"type":"codeVoice","code":"EmbeddedChannel"},{"type":"text","text":" is a "},{"type":"codeVoice","code":"Channel"},{"type":"text","text":" implementation that does neither any"},{"type":"text","text":" "},{"type":"text","text":"actual IO nor has a proper eventing mechanism. The prime use-case for"},{"type":"text","text":" "},{"type":"codeVoice","code":"EmbeddedChannel"},{"type":"text","text":" is in unit tests when you want to feed the inbound events"},{"type":"text","text":" "},{"type":"text","text":"and check the outbound events manually."}],"identifier":"doc:\/\/org.swift.docc\/documentation\/NIO\/EmbeddedChannel","kind":"symbol","type":"topic","navigatorTitle":[{"kind":"identifier","text":"EmbeddedChannel"}],"url":"\/documentation\/nio\/embeddedchannel"}}}